2025-04-24 18:41:00,404 INFO    MainThread:2209165 [wandb_init.py:setup_run_log_directory():724] Logging user logs to /home/ahteh/Developer/research/TreeMLP/wandb/run-20250424_184100-79hc3oyq/logs/debug.log
2025-04-24 18:41:00,404 INFO    MainThread:2209165 [wandb_init.py:setup_run_log_directory():725] Logging internal logs to /home/ahteh/Developer/research/TreeMLP/wandb/run-20250424_184100-79hc3oyq/logs/debug-internal.log
2025-04-24 18:41:00,404 INFO    MainThread:2209165 [wandb_init.py:monkeypatch_ipython():643] configuring jupyter hooks <wandb.sdk.wandb_init._WandbInit object at 0x7f7e7c2e2a50>
2025-04-24 18:41:00,405 INFO    MainThread:2209165 [wandb_init.py:init():852] calling init triggers
2025-04-24 18:41:00,406 INFO    MainThread:2209165 [wandb_init.py:init():857] wandb.init called with sweep_config: {}
config: {'dataset': 'physiochemical_protein', 'task_id': 361241, 'model': 'RandomForest', '_wandb': {}}
2025-04-24 18:41:00,406 INFO    MainThread:2209165 [wandb_init.py:init():893] starting backend
2025-04-24 18:41:00,407 INFO    MainThread:2209165 [wandb_init.py:init():897] sending inform_init request
2025-04-24 18:41:00,407 INFO    MainThread:2209165 [backend.py:_multiprocessing_setup():101] multiprocessing start_methods=fork,spawn,forkserver, using: spawn
2025-04-24 18:41:00,407 INFO    MainThread:2209165 [wandb_init.py:init():907] backend started and connected
2025-04-24 18:41:00,409 INFO    MainThread:2209165 [wandb_run.py:_label_probe_notebook():1369] probe notebook
2025-04-24 18:41:00,410 INFO    MainThread:2209165 [wandb_init.py:init():1002] updated telemetry
2025-04-24 18:41:00,425 INFO    MainThread:2209165 [wandb_init.py:init():1026] communicating run to backend with 90.0 second timeout
2025-04-24 18:41:00,754 INFO    MainThread:2209165 [wandb_init.py:init():1101] starting run threads in backend
2025-04-24 18:41:00,913 INFO    MainThread:2209165 [wandb_run.py:_console_start():2566] atexit reg
2025-04-24 18:41:00,913 INFO    MainThread:2209165 [wandb_run.py:_redirect():2414] redirect: wrap_raw
2025-04-24 18:41:00,914 INFO    MainThread:2209165 [wandb_run.py:_redirect():2483] Wrapping output streams.
2025-04-24 18:41:00,914 INFO    MainThread:2209165 [wandb_run.py:_redirect():2506] Redirects installed.
2025-04-24 18:41:00,914 INFO    MainThread:2209165 [wandb_init.py:init():1147] run started, returning control to user process
2025-04-24 18:41:18,159 WARNING MsgRouterThr:2209165 [router.py:message_loop():63] [no run ID] message_loop has been closed
Traceback (most recent call last):
  File "/home/ahteh/Developer/research/.venv/lib/python3.13/site-packages/wandb/sdk/interface/router_sock.py", line 27, in _read_message
    return self._sock_client.read_server_response(timeout=1)
           ~~~~~~~~~~~~~~~~~~~~~~~~~~~~~~~~~~~~~~^^^^^^^^^^^
  File "/home/ahteh/Developer/research/.venv/lib/python3.13/site-packages/wandb/sdk/lib/sock_client.py", line 235, in read_server_response
    data = self._read_packet_bytes(timeout=timeout)
  File "/home/ahteh/Developer/research/.venv/lib/python3.13/site-packages/wandb/sdk/lib/sock_client.py", line 220, in _read_packet_bytes
    raise SockClientClosedError
wandb.sdk.lib.sock_client.SockClientClosedError

The above exception was the direct cause of the following exception:

Traceback (most recent call last):
  File "/home/ahteh/Developer/research/.venv/lib/python3.13/site-packages/wandb/sdk/interface/router.py", line 56, in message_loop
    msg = self._read_message()
  File "/home/ahteh/Developer/research/.venv/lib/python3.13/site-packages/wandb/sdk/interface/router_sock.py", line 29, in _read_message
    raise MessageRouterClosedError from e
wandb.sdk.interface.router.MessageRouterClosedError
2025-04-24 18:41:18,167 INFO    MsgRouterThr:2209165 [mailbox.py:close():129] [no run ID] Closing mailbox, abandoning 10 handles.
2025-04-24 18:41:18,951 INFO    MainThread:2209165 [wandb_run.py:_finish():2314] finishing run spicecat-club/openml_regression_benchmark_2025/79hc3oyq
2025-04-24 18:41:18,951 INFO    MainThread:2209165 [jupyter.py:save_history():477] not saving jupyter history
2025-04-24 18:41:18,952 INFO    MainThread:2209165 [jupyter.py:save_ipynb():401] not saving jupyter notebook
2025-04-24 18:41:18,952 INFO    MainThread:2209165 [wandb_init.py:_jupyter_teardown():628] cleaning up jupyter logic
2025-04-24 18:41:18,953 INFO    MainThread:2209165 [wandb_run.py:_atexit_cleanup():2531] got exitcode: 0
2025-04-24 18:41:18,954 INFO    MainThread:2209165 [wandb_run.py:_restore():2513] restore
2025-04-24 18:41:18,955 INFO    MainThread:2209165 [wandb_run.py:_restore():2519] restore done
2025-04-24 18:41:18,955 INFO    MainThread:2209165 [wandb_run.py:_restore():2513] restore
2025-04-24 18:41:18,956 INFO    MainThread:2209165 [wandb_run.py:_restore():2519] restore done
2025-04-24 18:41:18,956 ERROR   MainThread:2209165 [wandb_run.py:_atexit_cleanup():2552] Problem finishing run
Traceback (most recent call last):
  File "/tmp/ipykernel_2209165/2787014074.py", line 30, in <module>
    metrics, pipe_fit = evaluate_model(name, model, X, y)
                        ~~~~~~~~~~~~~~^^^^^^^^^^^^^^^^^^^
  File "/tmp/ipykernel_2209165/2164441534.py", line 11, in evaluate_model
    cv_results = cross_validate(
        pipe, X, y, cv=cv, scoring=scoring, return_train_score=False, n_jobs=-1
    )
  File "/home/ahteh/Developer/research/.venv/lib/python3.13/site-packages/sklearn/utils/_param_validation.py", line 216, in wrapper
    return func(*args, **kwargs)
  File "/home/ahteh/Developer/research/.venv/lib/python3.13/site-packages/sklearn/model_selection/_validation.py", line 411, in cross_validate
    results = parallel(
        delayed(_fit_and_score)(
    ...<15 lines>...
        for train, test in indices
    )
  File "/home/ahteh/Developer/research/.venv/lib/python3.13/site-packages/sklearn/utils/parallel.py", line 77, in __call__
    return super().__call__(iterable_with_config)
           ~~~~~~~~~~~~~~~~^^^^^^^^^^^^^^^^^^^^^^
  File "/home/ahteh/Developer/research/.venv/lib/python3.13/site-packages/joblib/parallel.py", line 2007, in __call__
    return output if self.return_generator else list(output)
                                                ~~~~^^^^^^^^
  File "/home/ahteh/Developer/research/.venv/lib/python3.13/site-packages/joblib/parallel.py", line 1650, in _get_outputs
    yield from self._retrieve()
  File "/home/ahteh/Developer/research/.venv/lib/python3.13/site-packages/joblib/parallel.py", line 1762, in _retrieve
    time.sleep(0.01)
    ~~~~~~~~~~^^^^^^
KeyboardInterrupt

During handling of the above exception, another exception occurred:

Traceback (most recent call last):
  File "/home/ahteh/Developer/research/.venv/lib/python3.13/site-packages/wandb/sdk/wandb_run.py", line 2543, in _atexit_cleanup
    self._on_finish()
    ~~~~~~~~~~~~~~~^^
  File "/home/ahteh/Developer/research/.venv/lib/python3.13/site-packages/wandb/sdk/wandb_run.py", line 2790, in _on_finish
    exit_handle = self._backend.interface.deliver_exit(self._exit_code)
  File "/home/ahteh/Developer/research/.venv/lib/python3.13/site-packages/wandb/sdk/interface/interface.py", line 1006, in deliver_exit
    return self._deliver_exit(exit_data)
           ~~~~~~~~~~~~~~~~~~^^^^^^^^^^^
  File "/home/ahteh/Developer/research/.venv/lib/python3.13/site-packages/wandb/sdk/interface/interface_shared.py", line 436, in _deliver_exit
    return self._deliver_record(record)
           ~~~~~~~~~~~~~~~~~~~~^^^^^^^^
  File "/home/ahteh/Developer/research/.venv/lib/python3.13/site-packages/wandb/sdk/interface/interface_shared.py", line 389, in _deliver_record
    handle = mailbox.require_response(record)
  File "/home/ahteh/Developer/research/.venv/lib/python3.13/site-packages/wandb/sdk/mailbox/mailbox.py", line 68, in require_response
    raise MailboxClosedError()
wandb.sdk.mailbox.mailbox.MailboxClosedError
